Workbook

Sheet README
A1: Financial model - B1 circular ready-mix plant, Zuid-Holland (Rotterdam-Drechtsteden)
A2: Built by model/build_model.py from model/inputs.csv. Same model as model/model_core.py (checked: model/check_report.md).
A4: COLOUR CODE
A5: Blue font (yellow fill) = input you may change. Black font = live formula. Grey italic = value computed by model_core.py (not live). Green fill = check (must be 0).
A7: HOW IT WORKS
A8: 1. Inputs: every parameter has low/base/high. Cell Inputs!C3 picks the scenario (1 pessimistic, 2 base, 3 optimistic).
A9: Column H picks the column per parameter; column I is an OVERRIDE; column J is the ACTIVE value. Each active cell has a defined name = parameter name.
A10: Pessimistic = high column for cost-type inputs, low column for revenue-type inputs (column N 'direction'). 'fixed' inputs stay at base in all scenarios.
A11: 2. Capex -> Revenue -> Opex -> PnL -> CashFlow -> Valuation. Yearly sheets: column C = 2026 (t=0), D..M = 2027..2036 (t=1..10).
A12: 3. UnitEconomics: EUR/m3 stack for circular vs standard mix and plant average, for the year in UnitEconomics!C3.
A13: 4. Scenarios, Sensitivity, Viability criterion 4: computed with model_core.py (one model run per case) and pasted as values.
A15: KEY CONVENTIONS
... A36: model/inputs.csv, model/model_core.py, model/build_model.py, model/check_model.py, model/charts.py, model/charts/*.png, model/model_summary.md, model/check_report.md

Sheet Inputs
A1: Inputs - all model parameters (from model/inputs.csv) + option hooks
A3: ACTIVE SCENARIO (1 = pessimistic, 2 = base, 3 = optimistic) | C3: 2 | D3: =CHOOSE(scenario,"Pessimistic","Base","Optimistic") -> Base | F3: ACTIVE OPTION (0 = none; see Opt_Overview) | I3: 0
A4: Column H picks low/base/high per row: pessimistic uses column F, optimistic column G (1=low, 2=base, 3=high). Column I = OVERRIDE (leave empty = use H). Column O = value of the ACTIVE OPTION (cell I3, matrix on sheet Opt_Overview). Column J = ACTIVE value used by every formula (priority: Override > option > scenario; defined name = parameter name).
A5: parameter (= defined name) | B5: unit | C5: low | D5: base | E5: high | F5: pess. col | G5: opt. col | H5: scenario value | I5: OVERRIDE | J5: ACTIVE | K5: label | L5: source_ids | M5: notes | N5: direction | O5: option value
A6: price_basis | B6: - | C6: real 2026 EUR excl. VAT | D6: real 2026 EUR excl. VAT | E6: real 2026 EUR excl. VAT | F6: 2 | G6: 2 | H6: =INDEX(C6:E6,1,CHOOSE(scenario,F6,2,G6)) -> real 2026 EUR excl. VAT | J6: =IF(I6<>"",I6,IF(O6<>"",O6,H6)) -> real 2026 EUR excl. VAT | K6: ASSUMPTION | L6: plan.md | M6: All money in real 2026 EUR; general inflation = 0 in the model; only explicit real escalations below | N6: fixed | O6: =IFERROR(IF(option_sel=0,"",IF(LEN(INDEX(Opt_Overview!$C$7:$M$38,MATCH($A6,Opt_Overview!$A$7:$A$38,0),option_sel))=0,"",INDEX(Opt_Overview!$C$7:$M$38,MATCH($A6,Opt_Overview!$A$7:$A$38,0),option_sel))),"")
A7: general_inflation_real_model | B7: %/yr | C7: 0 | D7: 0 | E7: 0 | F7: 2 | G7: 2 | H7: =INDEX(C7:E7,1,CHOOSE(scenario,F7,2,G7)) -> 0 | J7: =IF(I7<>"",I7,IF(O7<>"",O7,H7)) -> 0 | K7: ASSUMPTION | L7: plan.md | M7: Real model. CBS CPI 2026 ~3.4% only used to convert older prices (TEC-44) | N7: fixed | O7: =IFERROR(IF(option_sel=0,"",IF(LEN(INDEX(Opt_Overview!$C$7:$M$38,MATCH($A7,Opt_Overview!$A$7:$A$38,0),option_sel))=0,"",INDEX(Opt_Overview!$C$7:$M$38,MATCH($A7,Opt_Overview!$A$7:$A$38,0),option_sel))),"")
A8: cpi_factor_2025_to_2026 | B8: x | C8: 1.02 | D8: 1.022 | E8: 1.03 | F8: 2 | G8: 2 | H8: =INDEX(C8:E8,1,CHOOSE(scenario,F8,2,G8)) -> 1.022 | J8: =IF(I8<>"",I8,IF(O8<>"",O8,H8)) -> 1.022 | K8: ESTIMATE | L8: MKT-54 | M8: CBS CPI Jan-2026 99.21 / Jan-2025 97.09 = 1.022; replaces placeholder A-CMP-15 | N8: fixed | O8: =IFERROR(IF(option_sel=0,"",IF(LEN(INDEX(Opt_Overview!$C$7:$M$38,MATCH($A8,Opt_Overview!$A$7:$A$38,0),option_sel))=0,"",INDEX(Opt_Overview!$C$7:$M$38,MATCH($A8,Opt_Overview!$A$7:$A$38,0),option_sel))),"")
A9: discount_rate_real | B9: % | C9: 6 | D9: 8 | E9: 10 | F9: 2 | G9: 2 | H9: =INDEX(C9:E9,1,CHOOSE(scenario,F9,2,G9)) -> 8 | J9: =IF(I9<>"",I9,IF(O9<>"",O9,H9)) -> 8 | K9: ASSUMPTION | L9: plan.md | M9: Client choice | N9: fixed | O9: =IFERROR(IF(option_sel=0,"",IF(LEN(INDEX(Opt_Overview!$C$7:$M$38,MATCH($A9,Opt_Overview!$A$7:$A$38,0),option_sel))=0,"",INDEX(Opt_Overview!$C$7:$M$38,MATCH($A9,Opt_Overview!$A$7:$A$38,0),option_sel))),"")
A10: tax_rate_vpb_low_bracket | B10: % | C10: 19 | D10: 19 | E10: 19 | F10: 2 | G10: 2 | H10: =INDEX(C10:E10,1,CHOOSE(scenario,F10,2,G10)) -> 19 | J10: =IF(I10<>"",I10,IF(O10<>"",O10,H10)) -> 19 | K10: ASSUMPTION | L10: A-CST-30 | M10: Dutch Vpb on first EUR 200k taxable profit (rate in force 2023-2026; not re-checked this session) | N10: fixed | O10: =IFERROR(IF(option_sel=0,"",IF(LEN(INDEX(Opt_Overview!$C$7:$M$38,MATCH($A10,Opt_Overview!$A$7:$A$38,0),option_sel))=0,"",INDEX(Opt_Overview!$C$7:$M$38,MATCH($A10,Opt_Overview!$A$7:$A$38,0),option_sel))),"")
A11: tax_vpb_low_bracket_limit | B11: EUR | C11: 200000 | D11: 200000 | E11: 200000 | F11: 2 | G11: 2 | H11: =INDEX(C11:E11,1,CHOOSE(scenario,F11,2,G11)) -> 200000 | J11: =IF(I11<>"",I11,IF(O11<>"",O11,H11)) -> 200000 | K11: ASSUMPTION | L11: A-CST-30 | N11: fixed | O11: =IFERROR(IF(option_sel=0,"",IF(LEN(INDEX(Opt_Overview!$C$7:$M$38,MATCH($A11,Opt_Overview!$A$7:$A$38,0),option_sel))=0,"",INDEX(Opt_Overview!$C$7:$M$38,MATCH($A11,Opt_Overview!$A$7:$A$38,0),option_sel))),"")
A12: tax_rate_vpb_high_bracket | B12: % | C12: 25.8 | D12: 25.8 | E12: 25.8 | F12: 2 | G12: 2 | H12: =INDEX(C12:E12,1,CHOOSE(scenario,F12,2,G12)) -> 25.8 | J12: =IF(I12<>"",I12,IF(O12<>"",O12,H12)) -> 25.8 | K12: ASSUMPTION | L12: A-CST-30 | M12: Above EUR 200k | N12: fixed | O12: =IFERROR(IF(option_sel=0,"",IF(LEN(INDEX(Opt_Overview!$C$7:$M$38,MATCH($A12,Opt_Overview!$A$7:$A$38,0),option_sel))=0,"",INDEX(Opt_Overview!$C$7:$M$38,MATCH($A12,Opt_Overview!$A$7:$A$38,0),option_sel))),"")
A13: mia_net_value_pct_eligible_capex | B13: % | C13: 7 | D13: 9.3 | E13: 11.6 | F13: 1 | G13: 3 | H13: =INDEX(C13:E13,1,CHOOSE(scenario,F13,2,G13)) -> 9.3 | J13: =IF(I13<>"",I13,IF(O13<>"",O13,H13)) -> 9.3 | K13: ESTIMATE | L13: A-POL-21 | M13: Only if taxable profit | N13: rev | O13: =IFERROR(IF(option_sel=0,"",IF(LEN(INDEX(Opt_Overview!$C$7:$M$38,MATCH($A13,Opt_Overview!$A$7:$A$38,0),option_sel))=0,"",INDEX(Opt_Overview!$C$7:$M$38,MATCH($A13,Opt_Overview!$A$7:$A$38,0),option_sel))),"")
A14: mia_eligible_share_of_capex | B14: % | C14: 0 | D14: 20 | E14: 50 | F14: 1 | G14: 3 | H14: =INDEX(C14:E14,1,CHOOSE(scenario,F14,2,G14)) -> 20 | J14: =IF(I14<>"",I14,IF(O14<>"",O14,H14)) -> 20 | K14: ASSUMPTION | L14: A-POL-22 | N14: rev | O14: =IFERROR(IF(option_sel=0,"",IF(LEN(INDEX(Opt_Overview!$C$7:$M$38,MATCH($A14,Opt_Overview!$A$7:$A$38,0),option_sel))=0,"",INDEX(Opt_Overview!$C$7:$M$38,MATCH($A14,Opt_Overview!$A$7:$A$38,0),option_sel))),"")
A15: grant_dei_veki_first_plant | B15: MEUR | C15: 0 | D15: 0.4 | E15: 1.5 | F15: 1 | G15: 3 | H15: =INDEX(C15:E15,1,CHOOSE(scenario,F15,2,G15)) -> 0.4 | J15: =IF(I15<>"",I15,IF(O15<>"",O15,H15)) -> 0.4 | K15: ASSUMPTION | L15: A-POL-24 | M15: Upside; competitive | N15: rev | O15: =IFERROR(IF(option_sel=0,"",IF(LEN(INDEX(Opt_Overview!$C$7:$M$38,MATCH($A15,Opt_Overview!$A$7:$A$38,0),option_sel))=0,"",INDEX(Opt_Overview!$C$7:$M$38,MATCH($A15,Opt_Overview!$A$7:$A$38,0),option_sel))),"")
A16: plant_capacity_hourly | B16: m3/h | C16: 100 | D16: 120 | E16: 150 | F16: 2 | G16: 2 | H16: =INDEX(C16:E16,1,CHOOSE(scenario,F16,2,G16)) -> 120 | J16: =IF(I16<>"",I16,IF(O16<>"",O16,H16)) -> 120 | K16: ESTIMATE | L16: A-TEC-23 | M16: Twin-shaft 3 m3 mixer | N16: fixed | O16: =IFERROR(IF(option_sel=0,"",IF(LEN(INDEX(Opt_Overview!$C$7:$M$38,MATCH($A16,Opt_Overview!$A$7:$A$38,0),option_sel))=0,"",INDEX(Opt_Overview!$C$7:$M$38,MATCH($A16,Opt_Overview!$A$7:$A$38,0),option_sel))),"")
A17: plant_capacity_theoretical | B17: m3/yr | C17: 200000 | D17: 240000 | E17: 280000 | F17: 2 | G17: 2 | H17: =INDEX(C17:E17,1,CHOOSE(scenario,F17,2,G17)) -> 240000 | J17: =IF(I17<>"",I17,IF(O17<>"",O17,H17)) -> 240000 | K17: ESTIMATE | L17: A-TEC-23 | M17: One shift ~2,000 h/yr | N17: fixed | O17: =IFERROR(IF(option_sel=0,"",IF(LEN(INDEX(Opt_Overview!$C$7:$M$38,MATCH($A17,Opt_Overview!$A$7:$A$38,0),option_sel))=0,"",INDEX(Opt_Overview!$C$7:$M$38,MATCH($A17,Opt_Overview!$A$7:$A$38,0),option_sel))),"")
A18: output_steady_state | B18: m3/yr | C18: 50000 | D18: 70000 | E18: 90000 | F18: 1 | G18: 3 | H18: =INDEX(C18:E18,1,CHOOSE(scenario,F18,2,G18)) -> 70000 | J18: =IF(I18<>"",I18,IF(O18<>"",O18,H18)) -> 70000 | K18: ESTIMATE | L18: A-TEC-24;A-MKT-32 | M18: Brief base 70k. MKT SOM base is 60k: test 60k. NL avg plant 33.7k m3 (CMP-43) | N18: rev | O18: =IFERROR(IF(option_sel=0,"",IF(LEN(INDEX(Opt_Overview!$C$7:$M$38,MATCH($A18,Opt_Overview!$A$7:$A$38,0),option_sel))=0,"",INDEX(Opt_Overview!$C$7:$M$38,MATCH($A18,Opt_Overview!$A$7:$A$38,0),option_sel))),"")
A19: ramp_year1_pct_of_steady | B19: % | C19: 35 | D19: 50 | E19: 65 | F19: 1 | G19: 3 | H19: =INDEX(C19:E19,1,CHOOSE(scenario,F19,2,G19)) -> 50 | J19: =IF(I19<>"",I19,IF(O19<>"",O19,H19)) -> 50 | K19: ASSUMPTION | L19: A-CST-01 | M19: First full operating year; base 35k m3 (TEC section 8) | N19: rev | O19: =IFERROR(IF(option_sel=0,"",IF(LEN(INDEX(Opt_Overview!$C$7:$M$38,MATCH($A19,Opt_Overview!$A$7:$A$38,0),option_sel))=0,"",INDEX(Opt_Overview!$C$7:$M$38,MATCH($A19,Opt_Overview!$A$7:$A$38,0),option_sel))),"")
A20: ramp_year2_pct_of_steady | B20: % | C20: 60 | D20: 79 | E20: 90 | F20: 1 | G20: 3 | H20: =INDEX(C20:E20,1,CHOOSE(scenario,F20,2,G20)) -> 79 | J20: =IF(I20<>"",I20,IF(O20<>"",O20,H20)) -> 79 | K20: ASSUMPTION | L20: A-CST-01 | M20: base 55k m3 | N20: rev | O20: =IFERROR(IF(option_sel=0,"",IF(LEN(INDEX(Opt_Overview!$C$7:$M$38,MATCH($A20,Opt_Overview!$A$7:$A$38,0),option_sel))=0,"",INDEX(Opt_Overview!$C$7:$M$38,MATCH($A20,Opt_Overview!$A$7:$A$38,0),option_sel))),"")
A21: ramp_year3plus_pct_of_steady | B21: % | C21: 85 | D21: 100 | E21: 100 | F21: 1 | G21: 3 | H21: =INDEX(C21:E21,1,CHOOSE(scenario,F21,2,G21)) -> 100 | J21: =IF(I21<>"",I21,IF(O21<>"",O21,H21)) -> 100 | K21: ASSUMPTION | L21: A-CST-01 | M21: base 70k m3 from year 3 | N21: rev | O21: =IFERROR(IF(option_sel=0,"",IF(LEN(INDEX(Opt_Overview!$C$7:$M$38,MATCH($A21,Opt_Overview!$A$7:$A$38,0),option_sel))=0,"",INDEX(Opt_Overview!$C$7:$M$38,MATCH($A21,Opt_Overview!$A$7:$A$38,0),option_sel))),"")
A22: circular_share_of_volume | B22: % | C22: 40 | D22: 60 | E22: 80 | F22: 1 | G22: 3 | H22: =INDEX(C22:E22,1,CHOOSE(scenario,F22,2,G22)) -> 60 | J22: =IF(I22<>"",I22,IF(O22<>"",O22,H22)) -> 60 | K22: ASSUMPTION | L22: A-TEC-44 | M22: Rest = standard CEM III/B mixes | N22: rev | O22: =IFERROR(IF(option_sel=0,"",IF(LEN(INDEX(Opt_Overview!$C$7:$M$38,MATCH($A22,Opt_Overview!$A$7:$A$38,0),option_sel))=0,"",INDEX(Opt_Overview!$C$7:$M$38,MATCH($A22,Opt_Overview!$A$7:$A$38,0),option_sel))),"")
A23: public_share_of_sales | B23: % | C23: 30 | D23: 40 | E23: 50 | F23: 1 | G23: 3 | H23: =INDEX(C23:E23,1,CHOOSE(scenario,F23,2,G23)) -> 40 | J23: =IF(I23<>"",I23,IF(O23<>"",O23,H23)) -> 40 | K23: ESTIMATE | L23: A-MKT-24 | M23: Public + housing corporations | N23: rev | O23: =IFERROR(IF(option_sel=0,"",IF(LEN(INDEX(Opt_Overview!$C$7:$M$38,MATCH($A23,Opt_Overview!$A$7:$A$38,0),option_sel))=0,"",INDEX(Opt_Overview!$C$7:$M$38,MATCH($A23,Opt_Overview!$A$7:$A$38,0),option_sel))),"")
A24: operating_days | B24: d/yr | C24: 220 | D24: 235 | E24: 250 | F24: 2 | G24: 2 | H24: =INDEX(C24:E24,1,CHOOSE(scenario,F24,2,G24)) -> 235 | J24: =IF(I24<>"",I24,IF(O24<>"",O24,H24)) -> 235 | K24: ASSUMPTION | L24: A-TEC-30 | N24: fixed | O24: =IFERROR(IF(option_sel=0,"",IF(LEN(INDEX(Opt_Overview!$C$7:$M$38,MATCH($A24,Opt_Overview!$A$7:$A$38,0),option_sel))=0,"",INDEX(Opt_Overview!$C$7:$M$38,MATCH($A24,Opt_Overview!$A$7:$A$38,0),option_sel))),"")
A25: capex_plant_equipment | B25: MEUR | C25: 3 | D25: 4 | E25: 5.5 | F25: 3 | G25: 1 | H25: =INDEX(C25:E25,1,CHOOSE(scenario,F25,2,G25)) -> 4 | J25: =IF(I25<>"",I25,IF(O25<>"",O25,H25)) -> 4 | K25: ASSUMPTION | L25: A-TEC-21;A-CST-02 | M25: Batching plant, mixer, 6-8 bins (3 RCA), 4-5 silos, covered RCA store, sprinklers, moisture probes, lab, wash-water recycling | N25: cost | O25: =IFERROR(IF(option_sel=0,"",IF(LEN(INDEX(Opt_Overview!$C$7:$M$38,MATCH($A25,Opt_Overview!$A$7:$A$38,0),option_sel))=0,"",INDEX(Opt_Overview!$C$7:$M$38,MATCH($A25,Opt_Overview!$A$7:$A$38,0),option_sel))),"")
A26: capex_site_prep_civil | B26: MEUR | C26: 0.6 | D26: 1 | E26: 1.8 | F26: 3 | G26: 1 | H26: =INDEX(C26:E26,1,CHOOSE(scenario,F26,2,G26)) -> 1 | J26: =IF(I26<>"",I26,IF(O26<>"",O26,H26)) -> 1 | K26: ASSUMPTION | L26: A-TEC-21;A-CST-02 | M26: Paving, foundations, drainage, grid connection, quay works. Sum with equipment+permits = 4.0/5.5/8.0 (brief) | N26: cost | O26: =IFERROR(IF(option_sel=0,"",IF(LEN(INDEX(Opt_Overview!$C$7:$M$38,MATCH($A26,Opt_Overview!$A$7:$A$38,0),option_sel))=0,"",INDEX(Opt_Overview!$C$7:$M$38,MATCH($A26,Opt_Overview!$A$7:$A$38,0),option_sel))),"")
A27: capex_permits_engineering | B27: MEUR | C27: 0.4 | D27: 0.5 | E27: 0.7 | F27: 3 | G27: 1 | H27: =INDEX(C27:E27,1,CHOOSE(scenario,F27,2,G27)) -> 0.5 | J27: =IF(I27<>"",I27,IF(O27<>"",O27,H27)) -> 0.5 | K27: ASSUMPTION | L27: A-CST-02 | M27: Permits, AERIUS/noise studies, engineering, start-up. Amortise 10 yr | N27: cost | O27: =IFERROR(IF(option_sel=0,"",IF(LEN(INDEX(Opt_Overview!$C$7:$M$38,MATCH($A27,Opt_Overview!$A$7:$A$38,0),option_sel))=0,"",INDEX(Opt_Overview!$C$7:$M$38,MATCH($A27,Opt_Overview!$A$7:$A$38,0),option_sel))),"")
A28: capex_lca_epd_one_off | B28: EUR | C28: 40000 | D28: 80000 | E28: 160000 | F28: 3 | G28: 1 | H28: =INDEX(C28:E28,1,CHOOSE(scenario,F28,2,G28)) -> 80000 | J28: =IF(I28<>"",I28,IF(O28<>"",O28,H28)) -> 80000 | K28: ASSUMPTION | L28: A-TEC-47;A-CST-03 | M28: 4 product families x EUR 20k (10-40k) | N28: cost | O28: =IFERROR(IF(option_sel=0,"",IF(LEN(INDEX(Opt_Overview!$C$7:$M$38,MATCH($A28,Opt_Overview!$A$7:$A$38,0),option_sel))=0,"",INDEX(Opt_Overview!$C$7:$M$38,MATCH($A28,Opt_Overview!$A$7:$A$38,0),option_sel))),"")
A29: capex_preopening_costs | B29: EUR | C29: 200000 | D29: 300000 | E29: 500000 | F29: 3 | G29: 1 | H29: =INDEX(C29:E29,1,CHOOSE(scenario,F29,2,G29)) -> 300000 | J29: =IF(I29<>"",I29,IF(O29<>"",O29,H29)) -> 300000 | K29: ASSUMPTION | L29: A-CST-04 | M29: Hiring before opening, trial mixes, initial type testing for KOMO | N29: cost | O29: =IFERROR(IF(option_sel=0,"",IF(LEN(INDEX(Opt_Overview!$C$7:$M$38,MATCH($A29,Opt_Overview!$A$7:$A$38,0),option_sel))=0,"",INDEX(Opt_Overview!$C$7:$M$38,MATCH($A29,Opt_Overview!$A$7:$A$38,0),option_sel))),"")
A30: capex_truck_mixers_option | B30: MEUR | C30: 1 | D30: 1.08 | E30: 1.2 | F30: 2 | G30: 2 | H30: =INDEX(C30:E30,1,CHOOSE(scenario,F30,2,G30)) -> 1.08 | J30: =IF(I30<>"",I30,IF(O30<>"",O30,H30)) -> 1.08 | K30: ESTIMATE | L30: A-TEC-31 | M30: Only if trucks bought (8 x EUR 135k); base = subcontracted | N30: fixed | O30: =IFERROR(IF(option_sel=0,"",IF(LEN(INDEX(Opt_Overview!$C$7:$M$38,MATCH($A30,Opt_Overview!$A$7:$A$38,0),option_sel))=0,"",INDEX(Opt_Overview!$C$7:$M$38,MATCH($A30,Opt_Overview!$A$7:$A$38,0),option_sel))),"")
A31: land_purchase | B31: MEUR | C31: 0 | D31: 0 | E31: 0 | F31: 2 | G31: 2 | H31: =INDEX(C31:E31,1,CHOOSE(scenario,F31,2,G31)) -> 0 | J31: =IF(I31<>"",I31,IF(O31<>"",O31,H31)) -> 0 | K31: ASSUMPTION | L31: A-CST-05 | M31: Land leased in base case | N31: fixed | O31: =IFERROR(IF(option_sel=0,"",IF(LEN(INDEX(Opt_Overview!$C$7:$M$38,MATCH($A31,Opt_Overview!$A$7:$A$38,0),option_sel))=0,"",INDEX(Opt_Overview!$C$7:$M$38,MATCH($A31,Opt_Overview!$A$7:$A$38,0),option_sel))),"")
A32: lifetime_plant_equipment | B32: yr | C32: 20 | D32: 25 | E32: 30 | F32: 2 | G32: 2 | H32: =INDEX(C32:E32,1,CHOOSE(scenario,F32,2,G32)) -> 25 | J32: =IF(I32<>"",I32,IF(O32<>"",O32,H32)) -> 25 | K32: ASSUMPTION | L32: A-TEC-39 | N32: fixed | O32: =IFERROR(IF(option_sel=0,"",IF(LEN(INDEX(Opt_Overview!$C$7:$M$38,MATCH($A32,Opt_Overview!$A$7:$A$38,0),option_sel))=0,"",INDEX(Opt_Overview!$C$7:$M$38,MATCH($A32,Opt_Overview!$A$7:$A$38,0),option_sel))),"")
A33: lifetime_civil_works | B33: yr | C33: 20 | D33: 25 | E33: 30 | F33: 2 | G33: 2 | H33: =INDEX(C33:E33,1,CHOOSE(scenario,F33,2,G33)) -> 25 | J33: =IF(I33<>"",I33,IF(O33<>"",O33,H33)) -> 25 | K33: ASSUMPTION | L33: A-TEC-39 | N33: fixed | O33: =IFERROR(IF(option_sel=0,"",IF(LEN(INDEX(Opt_Overview!$C$7:$M$38,MATCH($A33,Opt_Overview!$A$7:$A$38,0),option_sel))=0,"",INDEX(Opt_Overview!$C$7:$M$38,MATCH($A33,Opt_Overview!$A$7:$A$38,0),option_sel))),"")
A34: lifetime_permits_engineering | B34: yr | C34: 10 | D34: 10 | E34: 10 | F34: 2 | G34: 2 | H34: =INDEX(C34:E34,1,CHOOSE(scenario,F34,2,G34)) -> 10 | J34: =IF(I34<>"",I34,IF(O34<>"",O34,H34)) -> 10 | K34: ASSUMPTION | L34: A-CST-02 | N34: fixed | O34: =IFERROR(IF(option_sel=0,"",IF(LEN(INDEX(Opt_Overview!$C$7:$M$38,MATCH($A34,Opt_Overview!$A$7:$A$38,0),option_sel))=0,"",INDEX(Opt_Overview!$C$7:$M$38,MATCH($A34,Opt_Overview!$A$7:$A$38,0),option_sel))),"")
A35: salvage_value_yr10_pct_of_plant_civil_capex | B35: % | C35: 10 | D35: 25 | E35: 40 | F35: 1 | G35: 3 | H35: =INDEX(C35:E35,1,CHOOSE(scenario,F35,2,G35)) -> 25 | J35: =IF(I35<>"",I35,IF(O35<>"",O35,H35)) -> 25 | K35: ASSUMPTION | L35: A-CST-06 | M35: Terminal value = salvage only (plan 2.1). Used batching plants sell well below book value | N35: rev | O35: =IFERROR(IF(option_sel=0,"",IF(LEN(INDEX(Opt_Overview!$C$7:$M$38,MATCH($A35,Opt_Overview!$A$7:$A$38,0),option_sel))=0,"",INDEX(Opt_Overview!$C$7:$M$38,MATCH($A35,Opt_Overview!$A$7:$A$38,0),option_sel))),"")
A36: working_capital_receivable_days | B36: d | C36: 45 | D36: 60 | E36: 75 | F36: 3 | G36: 1 | H36: =INDEX(C36:E36,1,CHOOSE(scenario,F36,2,G36)) -> 60 | J36: =IF(I36<>"",I36,IF(O36<>"",O36,H36)) -> 60 | K36: ASSUMPTION | L36: A-CST-07 | M36: Dutch construction payment practice; contractors pay slowly | N36: cost | O36: =IFERROR(IF(option_sel=0,"",IF(LEN(INDEX(Opt_Overview!$C$7:$M$38,MATCH($A36,Opt_Overview!$A$7:$A$38,0),option_sel))=0,"",INDEX(Opt_Overview!$C$7:$M$38,MATCH($A36,Opt_Overview!$A$7:$A$38,0),option_sel))),"")
A37: working_capital_payable_days | B37: d | C37: 21 | D37: 30 | E37: 45 | F37: 1 | G37: 3 | H37: =INDEX(C37:E37,1,CHOOSE(scenario,F37,2,G37)) -> 30 | J37: =IF(I37<>"",I37,IF(O37<>"",O37,H37)) -> 30 | K37: ASSUMPTION | L37: A-CST-07 | M37: Cement and aggregate suppliers | N37: rev | O37: =IFERROR(IF(option_sel=0,"",IF(LEN(INDEX(Opt_Overview!$C$7:$M$38,MATCH($A37,Opt_Overview!$A$7:$A$38,0),option_sel))=0,"",INDEX(Opt_Overview!$C$7:$M$38,MATCH($A37,Opt_Overview!$A$7:$A$38,0),option_sel))),"")
A38: working_capital_inventory_days | B38: d | C38: 7 | D38: 10 | E38: 15 | F38: 3 | G38: 1 | H38: =INDEX(C38:E38,1,CHOOSE(scenario,F38,2,G38)) -> 10 | J38: =IF(I38<>"",I38,IF(O38<>"",O38,H38)) -> 10 | K38: ASSUMPTION | L38: A-CST-07 | M38: Of raw material cost | N38: cost | O38: =IFERROR(IF(option_sel=0,"",IF(LEN(INDEX(Opt_Overview!$C$7:$M$38,MATCH($A38,Opt_Overview!$A$7:$A$38,0),option_sel))=0,"",INDEX(Opt_Overview!$C$7:$M$38,MATCH($A38,Opt_Overview!$A$7:$A$38,0),option_sel))),"")
A39: sustaining_capex_pct_of_capex | B39: %/yr | C39: 0.5 | D39: 1 | E39: 2 | F39: 3 | G39: 1 | H39: =INDEX(C39:E39,1,CHOOSE(scenario,F39,2,G39)) -> 1 | J39: =IF(I39<>"",I39,IF(O39<>"",O39,H39)) -> 1 | K39: ASSUMPTION | L39: A-CST-08 | M39: On top of maintenance opex; mixer liners and wear parts are in maintenance | N39: cost | O39: =IFERROR(IF(option_sel=0,"",IF(LEN(INDEX(Opt_Overview!$C$7:$M$38,MATCH($A39,Opt_Overview!$A$7:$A$38,0),option_sel))=0,"",INDEX(Opt_Overview!$C$7:$M$38,MATCH($A39,Opt_Overview!$A$7:$A$38,0),option_sel))),"")
A40: mix_circ_binder | B40: kg/m3 | C40: 330 | D40: 345 | E40: 360 | F40: 2 | G40: 2 | H40: =INDEX(C40:E40,1,CHOOSE(scenario,F40,2,G40)) -> 345 | J40: =IF(I40<>"",I40,IF(O40<>"",O40,H40)) -> 345 | K40: ESTIMATE | L40: TEC-04;A-TEC-11;A-TEC-12;A-CST-09 | M40: CEM III/B | N40: fixed | O40: =IFERROR(IF(option_sel=0,"",IF(LEN(INDEX(Opt_Overview!$C$7:$M$38,MATCH($A40,Opt_Overview!$A$7:$A$38,0),option_sel))=0,"",INDEX(Opt_Overview!$C$7:$M$38,MATCH($A40,Opt_Overview!$A$7:$A$38,0),option_sel))),"")
A41: mix_circ_gravel | B41: kg/m3 | C41: 870 | D41: 620 | E41: 620 | F41: 2 | G41: 2 | H41: =INDEX(C41:E41,1,CHOOSE(scenario,F41,2,G41)) -> 620 | J41: =IF(I41<>"",I41,IF(O41<>"",O41,H41)) -> 620 | K41: ESTIMATE | L41: TEC-04;A-TEC-11;A-TEC-12;A-CST-09 | M41: Circular low = 30% RCA (V/V); base/high = 50% (CUR 112) | N41: fixed | O41: =IFERROR(IF(option_sel=0,"",IF(LEN(INDEX(Opt_Overview!$C$7:$M$38,MATCH($A41,Opt_Overview!$A$7:$A$38,0),option_sel))=0,"",INDEX(Opt_Overview!$C$7:$M$38,MATCH($A41,Opt_Overview!$A$7:$A$38,0),option_sel))),"")
...

Sheet UnitEconomics
A1: Unit economics - EUR per m3 delivered, circular vs standard (conventional) mix in the same plant
A3: Year index shown (1..10; 3 = 2029, first full-output year) | C3: 3 | D3: =2026+C3 -> 2029
A4: Fixed costs are spread equally over all m3 of that year. Delivery is subcontracted.
A6: Line (EUR/m3) | C6: Circular | D6: Standard CEM III/B | E6: Plant average | F6: Circular - standard
A7: Price (delivered) | C7: =INDEX(Revenue!$D$21:$M$21,1,$C$3) -> 137.38799 | D7: =INDEX(Revenue!$D$22:$M$22,1,$C$3) -> 135.75888 | E7: =(INDEX(Revenue!$D$25:$M$25,1,$C$3)+INDEX(Revenue!$D$26:$M$26,1,$C$3))/INDEX(Revenue!$D$8:$M$8,1,$C$3) -> 136.73634 | F7: =C7-D7 -> 1.6291066
A8: Cement | C8: =INDEX(Opex!$D$13:$M$13,1,$C$3) -> 36.7445 | D8: =INDEX(Opex!$D$21:$M$21,1,$C$3) -> 35.0486 | E8: =(INDEX(Revenue!$D$9:$M$9,1,$C$3)/INDEX(Revenue!$D$8:$M$8,1,$C$3))*C8+(1-(INDEX(Revenue!$D$9:$M$9,1,$C$3)/INDEX(Revenue!$D$8:$M$8,1,$C$3)))*D8 -> 36.06614 | F8: =C8-D8 -> 1.6959
A9: Gravel | C9: =INDEX(Opex!$D$14:$M$14,1,$C$3) -> 19.84 | D9: =INDEX(Opex!$D$22:$M$22,1,$C$3) -> 39.712 | E9: =(INDEX(Revenue!$D$9:$M$9,1,$C$3)/INDEX(Revenue!$D$8:$M$8,1,$C$3))*C9+(1-(INDEX(Revenue!$D$9:$M$9,1,$C$3)/INDEX(Revenue!$D$8:$M$8,1,$C$3)))*D9 -> 27.7888 | F9: =C9-D9 -> -19.872
A10: Recycled aggregate (delivered) | C10: =INDEX(Opex!$D$15:$M$15,1,$C$3) -> 13.72 | D10: =INDEX(Opex!$D$23:$M$23,1,$C$3) -> 0 | E10: =(INDEX(Revenue!$D$9:$M$9,1,$C$3)/INDEX(Revenue!$D$8:$M$8,1,$C$3))*C10+(1-(INDEX(Revenue!$D$9:$M$9,1,$C$3)/INDEX(Revenue!$D$8:$M$8,1,$C$3)))*D10 -> 8.232 | F10: =C10-D10 -> 13.72
A11: Sand | C11: =INDEX(Opex!$D$16:$M$16,1,$C$3) -> 11.97 | D11: =INDEX(Opex!$D$24:$M$24,1,$C$3) -> 12.141 | E11: =(INDEX(Revenue!$D$9:$M$9,1,$C$3)/INDEX(Revenue!$D$8:$M$8,1,$C$3))*C11+(1-(INDEX(Revenue!$D$9:$M$9,1,$C$3)/INDEX(Revenue!$D$8:$M$8,1,$C$3)))*D11 -> 12.0384 | F11: =C11-D11 -> -0.171
A12: Admixture (superplasticiser) | C12: =INDEX(Opex!$D$17:$M$17,1,$C$3) -> 4.095 | D12: =INDEX(Opex!$D$25:$M$25,1,$C$3) -> 3.038 | E12: =(INDEX(Revenue!$D$9:$M$9,1,$C$3)/INDEX(Revenue!$D$8:$M$8,1,$C$3))*C12+(1-(INDEX(Revenue!$D$9:$M$9,1,$C$3)/INDEX(Revenue!$D$8:$M$8,1,$C$3)))*D12 -> 3.6722 | F12: =C12-D12 -> 1.057
A13: Water | C13: =INDEX(Opex!$D$18:$M$18,1,$C$3) -> 0.2316 | D13: =INDEX(Opex!$D$26:$M$26,1,$C$3) -> 0.198 | E13: =(INDEX(Revenue!$D$9:$M$9,1,$C$3)/INDEX(Revenue!$D$8:$M$8,1,$C$3))*C13+(1-(INDEX(Revenue!$D$9:$M$9,1,$C$3)/INDEX(Revenue!$D$8:$M$8,1,$C$3)))*D13 -> 0.21816 | F13: =C13-D13 -> 0.0336
A14: RCA testing & handling | C14: =Opex!$C$8 -> 1.008 | D14: =0 -> 0 | E14: =(INDEX(Revenue!$D$9:$M$9,1,$C$3)/INDEX(Revenue!$D$8:$M$8,1,$C$3))*C14+(1-(INDEX(Revenue!$D$9:$M$9,1,$C$3)/INDEX(Revenue!$D$8:$M$8,1,$C$3)))*D14 -> 0.6048 | F14: =C14-D14 -> 1.008
A15: Energy | C15: =Opex!$C$9 -> 0.906 | D15: =Opex!$C$9 -> 0.906 | E15: =(INDEX(Revenue!$D$9:$M$9,1,$C$3)/INDEX(Revenue!$D$8:$M$8,1,$C$3))*C15+(1-(INDEX(Revenue!$D$9:$M$9,1,$C$3)/INDEX(Revenue!$D$8:$M$8,1,$C$3)))*D15 -> 0.906 | F15: =C15-D15 -> 0
A16: Variable cost delta (hook) | C16: =opt_cost_delta_per_m3 -> 0 | D16: =opt_cost_delta_per_m3 -> 0 | E16: =(INDEX(Revenue!$D$9:$M$9,1,$C$3)/INDEX(Revenue!$D$8:$M$8,1,$C$3))*C16+(1-(INDEX(Revenue!$D$9:$M$9,1,$C$3)/INDEX(Revenue!$D$8:$M$8,1,$C$3)))*D16 -> 0 | F16: =C16-D16 -> 0
A17: Circular-only cost delta (option) | C17: =IF(INDEX(Revenue!$D$9:$M$9,1,$C$3)>0,INDEX(Opex!$D$39:$M$39,1,$C$3)/INDEX(Revenue!$D$9:$M$9,1,$C$3),0) -> 0 | D17: =0 -> 0 | E17: =(INDEX(Revenue!$D$9:$M$9,1,$C$3)/INDEX(Revenue!$D$8:$M$8,1,$C$3))*C17+(1-(INDEX(Revenue!$D$9:$M$9,1,$C$3)/INDEX(Revenue!$D$8:$M$8,1,$C$3)))*D17 -> 0 | F17: =C17-D17 -> 0
A18: On-site crushing net cost per m3 (negative = net income, option A+B) | C18: =-(INDEX(Opex!$D$65:$M$65,1,$C$3)-INDEX(Revenue!$D$40:$M$40,1,$C$3)*bad_debt_pct_revenue/100)/INDEX(Revenue!$D$8:$M$8,1,$C$3) -> 0 | D18: =-(INDEX(Opex!$D$65:$M$65,1,$C$3)-INDEX(Revenue!$D$40:$M$40,1,$C$3)*bad_debt_pct_revenue/100)/INDEX(Revenue!$D$8:$M$8,1,$C$3) -> 0 | E18: =(INDEX(Revenue!$D$9:$M$9,1,$C$3)/INDEX(Revenue!$D$8:$M$8,1,$C$3))*C18+(1-(INDEX(Revenue!$D$9:$M$9,1,$C$3)/INDEX(Revenue!$D$8:$M$8,1,$C$3)))*D18 -> 0 | F18: =C18-D18 -> 0
A19: Production labour | C19: =INDEX(Opex!$D$48:$M$48,1,$C$3)/INDEX(Revenue!$D$8:$M$8,1,$C$3) -> 7.1055259 | D19: =INDEX(Opex!$D$48:$M$48,1,$C$3)/INDEX(Revenue!$D$8:$M$8,1,$C$3) -> 7.1055259 | E19: =(INDEX(Revenue!$D$9:$M$9,1,$C$3)/INDEX(Revenue!$D$8:$M$8,1,$C$3))*C19+(1-(INDEX(Revenue!$D$9:$M$9,1,$C$3)/INDEX(Revenue!$D$8:$M$8,1,$C$3)))*D19 -> 7.1055259 | F19: =C19-D19 -> 0
A20: Maintenance & wear | C20: =INDEX(Opex!$D$49:$M$49,1,$C$3)/INDEX(Revenue!$D$8:$M$8,1,$C$3) -> 1.7857143 | D20: =INDEX(Opex!$D$49:$M$49,1,$C$3)/INDEX(Revenue!$D$8:$M$8,1,$C$3) -> 1.7857143 | E20: =(INDEX(Revenue!$D$9:$M$9,1,$C$3)/INDEX(Revenue!$D$8:$M$8,1,$C$3))*C20+(1-(INDEX(Revenue!$D$9:$M$9,1,$C$3)/INDEX(Revenue!$D$8:$M$8,1,$C$3)))*D20 -> 1.7857143 | F20: =C20-D20 -> 0
A21: Certification & testing | C21: =INDEX(Opex!$D$50:$M$50,1,$C$3)/INDEX(Revenue!$D$8:$M$8,1,$C$3) -> 0.71428571 | D21: =INDEX(Opex!$D$50:$M$50,1,$C$3)/INDEX(Revenue!$D$8:$M$8,1,$C$3) -> 0.71428571 | E21: =(INDEX(Revenue!$D$9:$M$9,1,$C$3)/INDEX(Revenue!$D$8:$M$8,1,$C$3))*C21+(1-(INDEX(Revenue!$D$9:$M$9,1,$C$3)/INDEX(Revenue!$D$8:$M$8,1,$C$3)))*D21 -> 0.71428571 | F21: =C21-D21 -> 0
A22: Site lease | C22: =INDEX(Opex!$D$51:$M$51,1,$C$3)/INDEX(Revenue!$D$8:$M$8,1,$C$3) -> 2.1428571 | D22: =INDEX(Opex!$D$51:$M$51,1,$C$3)/INDEX(Revenue!$D$8:$M$8,1,$C$3) -> 2.1428571 | E22: =(INDEX(Revenue!$D$9:$M$9,1,$C$3)/INDEX(Revenue!$D$8:$M$8,1,$C$3))*C22+(1-(INDEX(Revenue!$D$9:$M$9,1,$C$3)/INDEX(Revenue!$D$8:$M$8,1,$C$3)))*D22 -> 2.1428571 | F22: =C22-D22 -> 0
A23: SG&A staff | C23: =INDEX(Opex!$D$52:$M$52,1,$C$3)/INDEX(Revenue!$D$8:$M$8,1,$C$3) -> 3.9152898 | D23: =INDEX(Opex!$D$52:$M$52,1,$C$3)/INDEX(Revenue!$D$8:$M$8,1,$C$3) -> 3.9152898 | E23: =(INDEX(Revenue!$D$9:$M$9,1,$C$3)/INDEX(Revenue!$D$8:$M$8,1,$C$3))*C23+(1-(INDEX(Revenue!$D$9:$M$9,1,$C$3)/INDEX(Revenue!$D$8:$M$8,1,$C$3)))*D23 -> 3.9152898 | F23: =C23-D23 -> 0
A24: SG&A non-staff | C24: =INDEX(Opex!$D$53:$M$53,1,$C$3)/INDEX(Revenue!$D$8:$M$8,1,$C$3) -> 4.2857143 | D24: =INDEX(Opex!$D$53:$M$53,1,$C$3)/INDEX(Revenue!$D$8:$M$8,1,$C$3) -> 4.2857143 | E24: =(INDEX(Revenue!$D$9:$M$9,1,$C$3)/INDEX(Revenue!$D$8:$M$8,1,$C$3))*C24+(1-(INDEX(Revenue!$D$9:$M$9,1,$C$3)/INDEX(Revenue!$D$8:$M$8,1,$C$3)))*D24 -> 4.2857143 | F24: =C24-D24 -> 0
A25: Extra fixed (hook) | C25: =INDEX(Opex!$D$54:$M$54,1,$C$3)/INDEX(Revenue!$D$8:$M$8,1,$C$3) -> 0 | D25: =INDEX(Opex!$D$54:$M$54,1,$C$3)/INDEX(Revenue!$D$8:$M$8,1,$C$3) -> 0 | E25: =(INDEX(Revenue!$D$9:$M$9,1,$C$3)/INDEX(Revenue!$D$8:$M$8,1,$C$3))*C25+(1-(INDEX(Revenue!$D$9:$M$9,1,$C$3)/INDEX(Revenue!$D$8:$M$8,1,$C$3)))*D25 -> 0 | F25: =C25-D25 -> 0
A26: Delivery (truck mixer) | C26: =Opex!$C$10 -> 19 | D26: =Opex!$C$10 -> 19 | E26: =(INDEX(Revenue!$D$9:$M$9,1,$C$3)/INDEX(Revenue!$D$8:$M$8,1,$C$3))*C26+(1-(INDEX(Revenue!$D$9:$M$9,1,$C$3)/INDEX(Revenue!$D$8:$M$8,1,$C$3)))*D26 -> 19 | F26: =C26-D26 -> 0
A27: Bad debt | C27: =C7*bad_debt_pct_revenue/100 -> 0.68693993 | D27: =D7*bad_debt_pct_revenue/100 -> 0.6787944 | E27: =(INDEX(Revenue!$D$9:$M$9,1,$C$3)/INDEX(Revenue!$D$8:$M$8,1,$C$3))*C27+(1-(INDEX(Revenue!$D$9:$M$9,1,$C$3)/INDEX(Revenue!$D$8:$M$8,1,$C$3)))*D27 -> 0.68368172 | F27: =C27-D27 -> 0.0081455328
A28: Cash cost (before depreciation) | C28: =SUM(C8:C27) -> 128.15143 | D28: =SUM(D8:D27) -> 130.67178 | E28: =SUM(E8:E27) -> 129.15957 | F28: =C28-D28 -> -2.5203545
A29: EBITDA margin | C29: =C7-C28 -> 9.2365596 | D29: =D7-D28 -> 5.0870985 | E29: =E7-E28 -> 7.5767751 | F29: =C29-D29 -> 4.149461
A30: Depreciation & amortisation | C30: =INDEX(Capex!$D$29:$M$29,1,$C$3)/INDEX(Revenue!$D$8:$M$8,1,$C$3) -> 3.6571429 | D30: =INDEX(Capex!$D$29:$M$29,1,$C$3)/INDEX(Revenue!$D$8:$M$8,1,$C$3) -> 3.6571429 | E30: =(INDEX(Revenue!$D$9:$M$9,1,$C$3)/INDEX(Revenue!$D$8:$M$8,1,$C$3))*C30+(1-(INDEX(Revenue!$D$9:$M$9,1,$C$3)/INDEX(Revenue!$D$8:$M$8,1,$C$3)))*D30 -> 3.6571429 | F30: =C30-D30 -> 0
A31: Total cost incl. depreciation | C31: =C28+C30 -> 131.80857 | D31: =D28+D30 -> 134.32892 | E31: =E28+E30 -> 132.81671 | F31: =C31-D31 -> -2.5203545
A32: EBIT margin | C32: =C7-C31 -> 5.5794167 | D32: =D7-D31 -> 1.4299557 | E32: =E7-E31 -> 3.9196323 | F32: =C32-D32 -> 4.149461
A33: Memo: capital recovery charge (10 yr annuity at r) | C33: =Valuation!$B$21/INDEX(Revenue!$D$8:$M$8,1,$C$3) -> 11.70946 | D33: =Valuation!$B$21/INDEX(Revenue!$D$8:$M$8,1,$C$3) -> 11.70946 | E33: =(INDEX(Revenue!$D$9:$M$9,1,$C$3)/INDEX(Revenue!$D$8:$M$8,1,$C$3))*C33+(1-(INDEX(Revenue!$D$9:$M$9,1,$C$3)/INDEX(Revenue!$D$8:$M$8,1,$C$3)))*D33 -> 11.70946 | F33: =C33-D33 -> 0
A34: Memo: EBITDA margin after capital charge | C34: =C29-C33 -> -2.4729003 | D34: =D29-D33 -> -6.6223613 | E34: =E29-E33 -> -4.1326847 | F34: =C34-D34 -> 4.149461
A36: Check: plant-average EBITDA x volume - P&L EBITDA (0 unless hook revenue) | E36: =E29*INDEX(Revenue!$D$8:$M$8,1,$C$3)-(INDEX(PnL!$D$35:$M$35,1,$C$3)-INDEX(Revenue!$D$27:$M$27,1,$C$3)) -> 0
A37: EBITDA margin as % of price | C37: =C29/C7 -> 0.067229747 | D37: =D29/D7 -> 0.037471571 | E37: =E29/E7 -> 0.055411567

Sheet Capex
A1: Capex, one-off start-up costs, grant, depreciation, salvage (EUR, real 2026)
A2: t=0 (2026) = permitting & construction year. All initial spend in t=0.
A3: Year | B3: unit | C3: =2026+C4 -> 2026 | D3: =2026+D4 -> 2027 | E3: =2026+E4 -> 2028 | F3: =2026+F4 -> 2029 | G3: =2026+G4 -> 2030 | H3: =2026+H4 -> 2031 | I3: =2026+I4 -> 2032 | J3: =2026+J4 -> 2033 | ... M3: =2026+M4 -> 2036
A4: t (year index) | C4: 0 | D4: 1 | E4: 2 | F4: 3 | G4: 4 | H4: 5 | I4: 6 | J4: 7 | K4: 8 | L4: 9 | M4: 10
A6: Initial investment (t = 0)
A7: Plant equipment (batching plant, mixer, bins, silos, lab) - in build year (2026 + delay) | B7: EUR | C7: =IF(C$4=opt_start_delay,capex_plant_equipment*1000000,0) -> 4000000 | D7: =IF(D$4=opt_start_delay,capex_plant_equipment*1000000,0) -> 0 | E7: =IF(E$4=opt_start_delay,capex_plant_equipment*1000000,0) -> 0 | F7: =IF(F$4=opt_start_delay,capex_plant_equipment*1000000,0) -> 0 | G7: =IF(G$4=opt_start_delay,capex_plant_equipment*1000000,0) -> 0 | H7: =IF(H$4=opt_start_delay,capex_plant_equipment*1000000,0) -> 0 | I7: =IF(I$4=opt_start_delay,capex_plant_equipment*1000000,0) -> 0 | J7: =IF(J$4=opt_start_delay,capex_plant_equipment*1000000,0) -> 0 | ... M7: =IF(M$4=opt_start_delay,capex_plant_equipment*1000000,0) -> 0
A8: Site preparation & civil works - in build year | B8: EUR | C8: =IF(C$4=opt_start_delay,capex_site_prep_civil*1000000,0) -> 1000000 | D8: =IF(D$4=opt_start_delay,capex_site_prep_civil*1000000,0) -> 0 | E8: =IF(E$4=opt_start_delay,capex_site_prep_civil*1000000,0) -> 0 | F8: =IF(F$4=opt_start_delay,capex_site_prep_civil*1000000,0) -> 0 | G8: =IF(G$4=opt_start_delay,capex_site_prep_civil*1000000,0) -> 0 | H8: =IF(H$4=opt_start_delay,capex_site_prep_civil*1000000,0) -> 0 | I8: =IF(I$4=opt_start_delay,capex_site_prep_civil*1000000,0) -> 0 | J8: =IF(J$4=opt_start_delay,capex_site_prep_civil*1000000,0) -> 0 | ... M8: =IF(M$4=opt_start_delay,capex_site_prep_civil*1000000,0) -> 0
A9: Permits, studies, engineering (amortised) - always 2026 | B9: EUR | C9: =capex_permits_engineering*1000000 -> 500000 | D9: 0 | E9: 0 | F9: 0 | G9: 0 | H9: 0 | I9: 0 | J9: 0 | K9: 0 | L9: 0 | M9: 0
A10: Option hook: extra capex - in build year | B10: EUR | C10: =IF(C$4=opt_start_delay,opt_extra_capex_y0,0) -> 0 | D10: =IF(D$4=opt_start_delay,opt_extra_capex_y0,0) -> 0 | E10: =IF(E$4=opt_start_delay,opt_extra_capex_y0,0) -> 0 | F10: =IF(F$4=opt_start_delay,opt_extra_capex_y0,0) -> 0 | G10: =IF(G$4=opt_start_delay,opt_extra_capex_y0,0) -> 0 | H10: =IF(H$4=opt_start_delay,opt_extra_capex_y0,0) -> 0 | I10: =IF(I$4=opt_start_delay,opt_extra_capex_y0,0) -> 0 | J10: =IF(J$4=opt_start_delay,opt_extra_capex_y0,0) -> 0 | ... M10: =IF(M$4=opt_start_delay,opt_extra_capex_y0,0) -> 0
A11: Land purchase (0 = leased) - in build year | B11: EUR | C11: =IF(C$4=opt_start_delay,land_purchase*1000000,0) -> 0 | D11: =IF(D$4=opt_start_delay,land_purchase*1000000,0) -> 0 | E11: =IF(E$4=opt_start_delay,land_purchase*1000000,0) -> 0 | F11: =IF(F$4=opt_start_delay,land_purchase*1000000,0) -> 0 | G11: =IF(G$4=opt_start_delay,land_purchase*1000000,0) -> 0 | H11: =IF(H$4=opt_start_delay,land_purchase*1000000,0) -> 0 | I11: =IF(I$4=opt_start_delay,land_purchase*1000000,0) -> 0 | J11: =IF(J$4=opt_start_delay,land_purchase*1000000,0) -> 0 | ... M11: =IF(M$4=opt_start_delay,land_purchase*1000000,0) -> 0
A12: Option A+B: year index of crushing-line capex (year before first crushing) | B12: t | C12: =MIN(10,MAX(0,ROUND(opt_crusher_start_year-2026,0)-1)) -> 0
A13: Option A+B: crushing-line capex | B13: EUR | C13: =IF(C$4=$C$12,opt_crusher_capex,0) -> 0 | D13: =IF(D$4=$C$12,opt_crusher_capex,0) -> 0 | E13: =IF(E$4=$C$12,opt_crusher_capex,0) -> 0 | F13: =IF(F$4=$C$12,opt_crusher_capex,0) -> 0 | G13: =IF(G$4=$C$12,opt_crusher_capex,0) -> 0 | H13: =IF(H$4=$C$12,opt_crusher_capex,0) -> 0 | I13: =IF(I$4=$C$12,opt_crusher_capex,0) -> 0 | J13: =IF(J$4=$C$12,opt_crusher_capex,0) -> 0 | ... M13: =IF(M$4=$C$12,opt_crusher_capex,0) -> 0
A14: Total initial capex | B14: EUR | C14: =C7+C8+C9+C10+C11+C13 -> 5500000 | D14: =D7+D8+D9+D10+D11+D13 -> 0 | E14: =E7+E8+E9+E10+E11+E13 -> 0 | F14: =F7+F8+F9+F10+F11+F13 -> 0 | G14: =G7+G8+G9+G10+G11+G13 -> 0 | H14: =H7+H8+H9+H10+H11+H13 -> 0 | I14: =I7+I8+I9+I10+I11+I13 -> 0 | J14: =J7+J8+J9+J10+J11+J13 -> 0 | ... M14: =M7+M8+M9+M10+M11+M13 -> 0
A15: Physical assets (plant + civil) - base for maintenance, sustaining capex, salvage | B15: EUR | C15: =SUM(Capex!$C$7:$M$7)+SUM(Capex!$C$8:$M$8) -> 5000000
A17: One-off items in t = 0 (expensed / income, not capex)
A18: Start-up costs expensed: LCA/EPD + pre-opening (build year) | B18: EUR | C18: =IF(C$4=opt_start_delay,capex_lca_epd_one_off+capex_preopening_costs,0) -> 380000 | D18: =IF(D$4=opt_start_delay,capex_lca_epd_one_off+capex_preopening_costs,0) -> 0 | E18: =IF(E$4=opt_start_delay,capex_lca_epd_one_off+capex_preopening_costs,0) -> 0 | F18: =IF(F$4=opt_start_delay,capex_lca_epd_one_off+capex_preopening_costs,0) -> 0 | G18: =IF(G$4=opt_start_delay,capex_lca_epd_one_off+capex_preopening_costs,0) -> 0 | H18: =IF(H$4=opt_start_delay,capex_lca_epd_one_off+capex_preopening_costs,0) -> 0 | I18: =IF(I$4=opt_start_delay,capex_lca_epd_one_off+capex_preopening_costs,0) -> 0 | J18: =IF(J$4=opt_start_delay,capex_lca_epd_one_off+capex_preopening_costs,0) -> 0 | ... M18: =IF(M$4=opt_start_delay,capex_lca_epd_one_off+capex_preopening_costs,0) -> 0
A19: Grant DEI+/VEKI (taxable income in build year) | B19: EUR | C19: =IF(C$4=opt_start_delay,grant_dei_veki_first_plant*1000000,0) -> 400000 | D19: =IF(D$4=opt_start_delay,grant_dei_veki_first_plant*1000000,0) -> 0 | E19: =IF(E$4=opt_start_delay,grant_dei_veki_first_plant*1000000,0) -> 0 | F19: =IF(F$4=opt_start_delay,grant_dei_veki_first_plant*1000000,0) -> 0 | G19: =IF(G$4=opt_start_delay,grant_dei_veki_first_plant*1000000,0) -> 0 | H19: =IF(H$4=opt_start_delay,grant_dei_veki_first_plant*1000000,0) -> 0 | I19: =IF(I$4=opt_start_delay,grant_dei_veki_first_plant*1000000,0) -> 0 | J19: =IF(J$4=opt_start_delay,grant_dei_veki_first_plant*1000000,0) -> 0 | ... M19: =IF(M$4=opt_start_delay,grant_dei_veki_first_plant*1000000,0) -> 0
A20: MIA extra tax deduction (gives the stated net value at top rate); plant in build year, crusher in its capex year | B20: EUR | C20: =IF(C$4=opt_start_delay,mia_eligible_share_of_capex/100*$C$15*mia_net_value_pct_eligible_capex/tax_rate_vpb_high_bracket,0)+IF(C$4=$C$12,opt_crusher_mia_share_pct/100*opt_crusher_capex*mia_net_value_pct_eligible_capex/tax_rate_vpb_high_bracket,0) -> 360465.12 | D20: =IF(D$4=opt_start_delay,mia_eligible_share_of_capex/100*$C$15*mia_net_value_pct_eligible_capex/tax_rate_vpb_high_bracket,0)+IF(D$4=$C$12,opt_crusher_mia_share_pct/100*opt_crusher_capex*mia_net_value_pct_eligible_capex/tax_rate_vpb_high_bracket,0) -> 0 | E20: =IF(E$4=opt_start_delay,mia_eligible_share_of_capex/100*$C$15*mia_net_value_pct_eligible_capex/tax_rate_vpb_high_bracket,0)+IF(E$4=$C$12,opt_crusher_mia_share_pct/100*opt_crusher_capex*mia_net_value_pct_eligible_capex/tax_rate_vpb_high_bracket,0) -> 0 | F20: =IF(F$4=opt_start_delay,mia_eligible_share_of_capex/100*$C$15*mia_net_value_pct_eligible_capex/tax_rate_vpb_high_bracket,0)+IF(F$4=$C$12,opt_crusher_mia_share_pct/100*opt_crusher_capex*mia_net_value_pct_eligible_capex/tax_rate_vpb_high_bracket,0) -> 0 | G20: =IF(G$4=opt_start_delay,mia_eligible_share_of_capex/100*$C$15*mia_net_value_pct_eligible_capex/tax_rate_vpb_high_bracket,0)+IF(G$4=$C$12,opt_crusher_mia_share_pct/100*opt_crusher_capex*mia_net_value_pct_eligible_capex/tax_rate_vpb_high_bracket,0) -> 0 | H20: =IF(H$4=opt_start_delay,mia_eligible_share_of_capex/100*$C$15*mia_net_value_pct_eligible_capex/tax_rate_vpb_high_bracket,0)+IF(H$4=$C$12,opt_crusher_mia_share_pct/100*opt_crusher_capex*mia_net_value_pct_eligible_capex/tax_rate_vpb_high_bracket,0) -> 0 | I20: =IF(I$4=opt_start_delay,mia_eligible_share_of_capex/100*$C$15*mia_net_value_pct_eligible_capex/tax_rate_vpb_high_bracket,0)+IF(I$4=$C$12,opt_crusher_mia_share_pct/100*opt_crusher_capex*mia_net_value_pct_eligible_capex/tax_rate_vpb_high_bracket,0) -> 0 | J20: =IF(J$4=opt_start_delay,mia_eligible_share_of_capex/100*$C$15*mia_net_value_pct_eligible_capex/tax_rate_vpb_high_bracket,0)+IF(J$4=$C$12,opt_crusher_mia_share_pct/100*opt_crusher_capex*mia_net_value_pct_eligible_capex/tax_rate_vpb_high_bracket,0) -> 0 | ... M20: =IF(M$4=opt_start_delay,mia_eligible_share_of_capex/100*$C$15*mia_net_value_pct_eligible_capex/tax_rate_vpb_high_bracket,0)+IF(M$4=$C$12,opt_crusher_mia_share_pct/100*opt_crusher_capex*mia_net_value_pct_eligible_capex/tax_rate_vpb_high_bracket,0) -> 0
A22: Sustaining capex and depreciation
A23: Sustaining capex (% of physical assets per operating year) | B23: EUR | C23: =IF(C$4>=(1+opt_start_delay),sustaining_capex_pct_of_capex/100*$C$15,0) -> 0 | D23: =IF(D$4>=(1+opt_start_delay),sustaining_capex_pct_of_capex/100*$C$15,0) -> 50000 | E23: =IF(E$4>=(1+opt_start_delay),sustaining_capex_pct_of_capex/100*$C$15,0) -> 50000 | F23: =IF(F$4>=(1+opt_start_delay),sustaining_capex_pct_of_capex/100*$C$15,0) -> 50000 | G23: =IF(G$4>=(1+opt_start_delay),sustaining_capex_pct_of_capex/100*$C$15,0) -> 50000 | H23: =IF(H$4>=(1+opt_start_delay),sustaining_capex_pct_of_capex/100*$C$15,0) -> 50000 | I23: =IF(I$4>=(1+opt_start_delay),sustaining_capex_pct_of_capex/100*$C$15,0) -> 50000 | J23: =IF(J$4>=(1+opt_start_delay),sustaining_capex_pct_of_capex/100*$C$15,0) -> 50000 | ... M23: =IF(M$4>=(1+opt_start_delay),sustaining_capex_pct_of_capex/100*$C$15,0) -> 50000
A24: Depreciation plant equipment (+ hook capex), from first operating year | B24: EUR | C24: =IF(AND(C$4>=(1+opt_start_delay),C$4<(1+opt_start_delay)+lifetime_plant_equipment),(SUM(Capex!$C$7:$M$7)+SUM(Capex!$C$10:$M$10))/lifetime_plant_equipment,0) -> 0 | D24: =IF(AND(D$4>=(1+opt_start_delay),D$4<(1+opt_start_delay)+lifetime_plant_equipment),(SUM(Capex!$C$7:$M$7)+SUM(Capex!$C$10:$M$10))/lifetime_plant_equipment,0) -> 160000 | E24: =IF(AND(E$4>=(1+opt_start_delay),E$4<(1+opt_start_delay)+lifetime_plant_equipment),(SUM(Capex!$C$7:$M$7)+SUM(Capex!$C$10:$M$10))/lifetime_plant_equipment,0) -> 160000 | F24: =IF(AND(F$4>=(1+opt_start_delay),F$4<(1+opt_start_delay)+lifetime_plant_equipment),(SUM(Capex!$C$7:$M$7)+SUM(Capex!$C$10:$M$10))/lifetime_plant_equipment,0) -> 160000 | G24: =IF(AND(G$4>=(1+opt_start_delay),G$4<(1+opt_start_delay)+lifetime_plant_equipment),(SUM(Capex!$C$7:$M$7)+SUM(Capex!$C$10:$M$10))/lifetime_plant_equipment,0) -> 160000 | H24: =IF(AND(H$4>=(1+opt_start_delay),H$4<(1+opt_start_delay)+lifetime_plant_equipment),(SUM(Capex!$C$7:$M$7)+SUM(Capex!$C$10:$M$10))/lifetime_plant_equipment,0) -> 160000 | I24: =IF(AND(I$4>=(1+opt_start_delay),I$4<(1+opt_start_delay)+lifetime_plant_equipment),(SUM(Capex!$C$7:$M$7)+SUM(Capex!$C$10:$M$10))/lifetime_plant_equipment,0) -> 160000 | J24: =IF(AND(J$4>=(1+opt_start_delay),J$4<(1+opt_start_delay)+lifetime_plant_equipment),(SUM(Capex!$C$7:$M$7)+SUM(Capex!$C$10:$M$10))/lifetime_plant_equipment,0) -> 160000 | ... M24: =IF(AND(M$4>=(1+opt_start_delay),M$4<(1+opt_start_delay)+lifetime_plant_equipment),(SUM(Capex!$C$7:$M$7)+SUM(Capex!$C$10:$M$10))/lifetime_plant_equipment,0) -> 160000
A25: Depreciation civil works | B25: EUR | C25: =IF(AND(C$4>=(1+opt_start_delay),C$4<(1+opt_start_delay)+lifetime_civil_works),SUM(Capex!$C$8:$M$8)/lifetime_civil_works,0) -> 0 | D25: =IF(AND(D$4>=(1+opt_start_delay),D$4<(1+opt_start_delay)+lifetime_civil_works),SUM(Capex!$C$8:$M$8)/lifetime_civil_works,0) -> 40000 | E25: =IF(AND(E$4>=(1+opt_start_delay),E$4<(1+opt_start_delay)+lifetime_civil_works),SUM(Capex!$C$8:$M$8)/lifetime_civil_works,0) -> 40000 | F25: =IF(AND(F$4>=(1+opt_start_delay),F$4<(1+opt_start_delay)+lifetime_civil_works),SUM(Capex!$C$8:$M$8)/lifetime_civil_works,0) -> 40000 | G25: =IF(AND(G$4>=(1+opt_start_delay),G$4<(1+opt_start_delay)+lifetime_civil_works),SUM(Capex!$C$8:$M$8)/lifetime_civil_works,0) -> 40000 | H25: =IF(AND(H$4>=(1+opt_start_delay),H$4<(1+opt_start_delay)+lifetime_civil_works),SUM(Capex!$C$8:$M$8)/lifetime_civil_works,0) -> 40000 | I25: =IF(AND(I$4>=(1+opt_start_delay),I$4<(1+opt_start_delay)+lifetime_civil_works),SUM(Capex!$C$8:$M$8)/lifetime_civil_works,0) -> 40000 | J25: =IF(AND(J$4>=(1+opt_start_delay),J$4<(1+opt_start_delay)+lifetime_civil_works),SUM(Capex!$C$8:$M$8)/lifetime_civil_works,0) -> 40000 | ... M25: =IF(AND(M$4>=(1+opt_start_delay),M$4<(1+opt_start_delay)+lifetime_civil_works),SUM(Capex!$C$8:$M$8)/lifetime_civil_works,0) -> 40000
A26: Amortisation permits & engineering | B26: EUR | C26: =IF(AND(C$4>=(1+opt_start_delay),C$4<(1+opt_start_delay)+lifetime_permits_engineering),$C$9/lifetime_permits_engineering,0) -> 0 | D26: =IF(AND(D$4>=(1+opt_start_delay),D$4<(1+opt_start_delay)+lifetime_permits_engineering),$C$9/lifetime_permits_engineering,0) -> 50000 | E26: =IF(AND(E$4>=(1+opt_start_delay),E$4<(1+opt_start_delay)+lifetime_permits_engineering),$C$9/lifetime_permits_engineering,0) -> 50000 | F26: =IF(AND(F$4>=(1+opt_start_delay),F$4<(1+opt_start_delay)+lifetime_permits_engineering),$C$9/lifetime_permits_engineering,0) -> 50000 | G26: =IF(AND(G$4>=(1+opt_start_delay),G$4<(1+opt_start_delay)+lifetime_permits_engineering),$C$9/lifetime_permits_engineering,0) -> 50000 | H26: =IF(AND(H$4>=(1+opt_start_delay),H$4<(1+opt_start_delay)+lifetime_permits_engineering),$C$9/lifetime_permits_engineering,0) -> 50000 | I26: =IF(AND(I$4>=(1+opt_start_delay),I$4<(1+opt_start_delay)+lifetime_permits_engineering),$C$9/lifetime_permits_engineering,0) -> 50000 | J26: =IF(AND(J$4>=(1+opt_start_delay),J$4<(1+opt_start_delay)+lifetime_permits_engineering),$C$9/lifetime_permits_engineering,0) -> 50000 | ... M26: =IF(AND(M$4>=(1+opt_start_delay),M$4<(1+opt_start_delay)+lifetime_permits_engineering),$C$9/lifetime_permits_engineering,0) -> 50000
A27: Depreciation crushing line (option A+B) | B27: EUR | C27: =IF(AND(C$4>=$C$12+1,C$4<$C$12+1+hybrid_crusher_lifetime),opt_crusher_capex/hybrid_crusher_lifetime,0) -> 0 | D27: =IF(AND(D$4>=$C$12+1,D$4<$C$12+1+hybrid_crusher_lifetime),opt_crusher_capex/hybrid_crusher_lifetime,0) -> 0 | E27: =IF(AND(E$4>=$C$12+1,E$4<$C$12+1+hybrid_crusher_lifetime),opt_crusher_capex/hybrid_crusher_lifetime,0) -> 0 | F27: =IF(AND(F$4>=$C$12+1,F$4<$C$12+1+hybrid_crusher_lifetime),opt_crusher_capex/hybrid_crusher_lifetime,0) -> 0 | G27: =IF(AND(G$4>=$C$12+1,G$4<$C$12+1+hybrid_crusher_lifetime),opt_crusher_capex/hybrid_crusher_lifetime,0) -> 0 | H27: =IF(AND(H$4>=$C$12+1,H$4<$C$12+1+hybrid_crusher_lifetime),opt_crusher_capex/hybrid_crusher_lifetime,0) -> 0 | I27: =IF(AND(I$4>=$C$12+1,I$4<$C$12+1+hybrid_crusher_lifetime),opt_crusher_capex/hybrid_crusher_lifetime,0) -> 0 | J27: =IF(AND(J$4>=$C$12+1,J$4<$C$12+1+hybrid_crusher_lifetime),opt_crusher_capex/hybrid_crusher_lifetime,0) -> 0 | ... M27: =IF(AND(M$4>=$C$12+1,M$4<$C$12+1+hybrid_crusher_lifetime),opt_crusher_capex/hybrid_crusher_lifetime,0) -> 0
A28: Depreciation sustaining capex (plant life) | B28: EUR | C28: =SUM($C$23:C23)/lifetime_plant_equipment -> 0 | D28: =SUM($C$23:D23)/lifetime_plant_equipment -> 2000 | E28: =SUM($C$23:E23)/lifetime_plant_equipment -> 4000 | F28: =SUM($C$23:F23)/lifetime_plant_equipment -> 6000 | G28: =SUM($C$23:G23)/lifetime_plant_equipment -> 8000 | H28: =SUM($C$23:H23)/lifetime_plant_equipment -> 10000 | I28: =SUM($C$23:I23)/lifetime_plant_equipment -> 12000 | J28: =SUM($C$23:J23)/lifetime_plant_equipment -> 14000 | ... M28: =SUM($C$23:M23)/lifetime_plant_equipment -> 20000
A29: Total depreciation & amortisation | B29: EUR | C29: =C24+C25+C26+C27+C28 -> 0 | D29: =D24+D25+D26+D27+D28 -> 252000 | E29: =E24+E25+E26+E27+E28 -> 254000 | F29: =F24+F25+F26+F27+F28 -> 256000 | G29: =G24+G25+G26+G27+G28 -> 258000 | H29: =H24+H25+H26+H27+H28 -> 260000 | I29: =I24+I25+I26+I27+I28 -> 262000 | J29: =J24+J25+J26+J27+J28 -> 264000 | ... M29: =M24+M25+M26+M27+M28 -> 270000
A30: Memo: net book value end of year (excl. land) | B30: EUR | C30: =SUM($C$14:C14)-SUM($C$11:C11)+SUM($C$23:C23)-SUM($C$29:C29) -> 5500000 | D30: =SUM($C$14:D14)-SUM($C$11:D11)+SUM($C$23:D23)-SUM($C$29:D29) -> 5298000 | E30: =SUM($C$14:E14)-SUM($C$11:E11)+SUM($C$23:E23)-SUM($C$29:E29) -> 5094000 | F30: =SUM($C$14:F14)-SUM($C$11:F11)+SUM($C$23:F23)-SUM($C$29:F29) -> 4888000 | G30: =SUM($C$14:G14)-SUM($C$11:G11)+SUM($C$23:G23)-SUM($C$29:G29) -> 4680000 | H30: =SUM($C$14:H14)-SUM($C$11:H11)+SUM($C$23:H23)-SUM($C$29:H29) -> 4470000 | I30: =SUM($C$14:I14)-SUM($C$11:I11)+SUM($C$23:I23)-SUM($C$29:I29) -> 4258000 | J30: =SUM($C$14:J14)-SUM($C$11:J11)+SUM($C$23:J23)-SUM($C$29:J29) -> 4044000 | ... M30: =SUM($C$14:M14)-SUM($C$11:M11)+SUM($C$23:M23)-SUM($C$29:M29) -> 3390000
A31: Salvage value in t=10 (= the ONLY terminal value; plant+civil and crushing line) | B31: EUR | C31: =IF(C$4=10,salvage_value_yr10_pct_of_plant_civil_capex/100*$C$15+opt_crusher_salvage_pct/100*opt_crusher_capex,0) -> 0 | D31: =IF(D$4=10,salvage_value_yr10_pct_of_plant_civil_capex/100*$C$15+opt_crusher_salvage_pct/100*opt_crusher_capex,0) -> 0 | E31: =IF(E$4=10,salvage_value_yr10_pct_of_plant_civil_capex/100*$C$15+opt_crusher_salvage_pct/100*opt_crusher_capex,0) -> 0 | F31: =IF(F$4=10,salvage_value_yr10_pct_of_plant_civil_capex/100*$C$15+opt_crusher_salvage_pct/100*opt_crusher_capex,0) -> 0 | G31: =IF(G$4=10,salvage_value_yr10_pct_of_plant_civil_capex/100*$C$15+opt_crusher_salvage_pct/100*opt_crusher_capex,0) -> 0 | H31: =IF(H$4=10,salvage_value_yr10_pct_of_plant_civil_capex/100*$C$15+opt_crusher_salvage_pct/100*opt_crusher_capex,0) -> 0 | I31: =IF(I$4=10,salvage_value_yr10_pct_of_plant_civil_capex/100*$C$15+opt_crusher_salvage_pct/100*opt_crusher_capex,0) -> 0 | J31: =IF(J$4=10,salvage_value_yr10_pct_of_plant_civil_capex/100*$C$15+opt_crusher_salvage_pct/100*opt_crusher_capex,0) -> 0 | ... M31: =IF(M$4=10,salvage_value_yr10_pct_of_plant_civil_capex/100*$C$15+opt_crusher_salvage_pct/100*opt_crusher_capex,0) -> 1250000

Sheet Revenue
A1: Volume, prices and revenue
A2: Plant-average price over all strength classes (Agent 5). Premium only on circular volume.
A3: Year | B3: unit | C3: =2026+C4 -> 2026 | D3: =2026+D4 -> 2027 | E3: =2026+E4 -> 2028 | F3: =2026+F4 -> 2029 | G3: =2026+G4 -> 2030 | H3: =2026+H4 -> 2031 | I3: =2026+I4 -> 2032 | J3: =2026+J4 -> 2033 | ... M3: =2026+M4 -> 2036
A4: t (year index) | C4: 0 | D4: 1 | E4: 2 | F4: 3 | G4: 4 | H4: 5 | I4: 6 | J4: 7 | K4: 8 | L4: 9 | M4: 10
A6: Volume
A7: Utilisation of steady-state output (ramp-up) | B7: % | C7: =IF(C$4<1+opt_start_delay,0,IF(C$4=1+opt_start_delay,ramp_year1_pct_of_steady/100,IF(C$4=2+opt_start_delay,ramp_year2_pct_of_steady/100,ramp_year3plus_pct_of_steady/100))) -> 0 | D7: =IF(D$4<1+opt_start_delay,0,IF(D$4=1+opt_start_delay,ramp_year1_pct_of_steady/100,IF(D$4=2+opt_start_delay,ramp_year2_pct_of_steady/100,ramp_year3plus_pct_of_steady/100))) -> 0.5 | E7: =IF(E$4<1+opt_start_delay,0,IF(E$4=1+opt_start_delay,ramp_year1_pct_of_steady/100,IF(E$4=2+opt_start_delay,ramp_year2_pct_of_steady/100,ramp_year3plus_pct_of_steady/100))) -> 0.79 | F7: =IF(F$4<1+opt_start_delay,0,IF(F$4=1+opt_start_delay,ramp_year1_pct_of_steady/100,IF(F$4=2+opt_start_delay,ramp_year2_pct_of_steady/100,ramp_year3plus_pct_of_steady/100))) -> 1 | G7: =IF(G$4<1+opt_start_delay,0,IF(G$4=1+opt_start_delay,ramp_year1_pct_of_steady/100,IF(G$4=2+opt_start_delay,ramp_year2_pct_of_steady/100,ramp_year3plus_pct_of_steady/100))) -> 1 | H7: =IF(H$4<1+opt_start_delay,0,IF(H$4=1+opt_start_delay,ramp_year1_pct_of_steady/100,IF(H$4=2+opt_start_delay,ramp_year2_pct_of_steady/100,ramp_year3plus_pct_of_steady/100))) -> 1 | I7: =IF(I$4<1+opt_start_delay,0,IF(I$4=1+opt_start_delay,ramp_year1_pct_of_steady/100,IF(I$4=2+opt_start_delay,ramp_year2_pct_of_steady/100,ramp_year3plus_pct_of_steady/100))) -> 1 | J7: =IF(J$4<1+opt_start_delay,0,IF(J$4=1+opt_start_delay,ramp_year1_pct_of_steady/100,IF(J$4=2+opt_start_delay,ramp_year2_pct_of_steady/100,ramp_year3plus_pct_of_steady/100))) -> 1 | ... M7: =IF(M$4<1+opt_start_delay,0,IF(M$4=1+opt_start_delay,ramp_year1_pct_of_steady/100,IF(M$4=2+opt_start_delay,ramp_year2_pct_of_steady/100,ramp_year3plus_pct_of_steady/100))) -> 1
A8: Volume sold | B8: m3 | C8: =output_steady_state*C7 -> 0 | D8: =output_steady_state*D7 -> 35000 | E8: =output_steady_state*E7 -> 55300 | F8: =output_steady_state*F7 -> 70000 | G8: =output_steady_state*G7 -> 70000 | H8: =output_steady_state*H7 -> 70000 | I8: =output_steady_state*I7 -> 70000 | J8: =output_steady_state*J7 -> 70000 | ... M8: =output_steady_state*M7 -> 70000
A9: of which circular mixes (50% coarse RCA) | B9: m3 | C9: =C8*circular_share_of_volume/100 -> 0 | D9: =D8*circular_share_of_volume/100 -> 21000 | E9: =E8*circular_share_of_volume/100 -> 33180 | F9: =F8*circular_share_of_volume/100 -> 42000 | G9: =G8*circular_share_of_volume/100 -> 42000 | H9: =H8*circular_share_of_volume/100 -> 42000 | I9: =I8*circular_share_of_volume/100 -> 42000 | J9: =J8*circular_share_of_volume/100 -> 42000 | ... M9: =M8*circular_share_of_volume/100 -> 42000
A10: of which standard CEM III/B mixes | B10: m3 | C10: =C8-C9 -> 0 | D10: =D8-D9 -> 14000 | E10: =E8-E9 -> 22120 | F10: =F8-F9 -> 28000 | G10: =G8-G9 -> 28000 | H10: =H8-H9 -> 28000 | I10: =I8-I9 -> 28000 | J10: =J8-J9 -> 28000 | ... M10: =M8-M9 -> 28000
A12: Cement price path (CEM III/B, delivered)
A13: Carbon cost in CEM III/B price (ETS/CBAM) | B13: EUR/t | C13: =carbon_cost_cem3b_2026 -> 3.8 | D13: =carbon_cost_cem3b_2027 -> 4.3 | E13: =carbon_cost_cem3b_2028 -> 5.2 | F13: =carbon_cost_cem3b_2029 -> 7.4 | G13: =carbon_cost_cem3b_2030 -> 12.1 | H13: =carbon_cost_cem3b_2031 -> 14.8 | I13: =carbon_cost_cem3b_2032 -> 17.9 | J13: =carbon_cost_cem3b_2033 -> 21.5 | K13: =carbon_cost_cem3b_2034 -> 25.6 | L13: =carbon_cost_cem3b_2035 -> 25.6 | M13: =carbon_cost_cem3b_2036 -> 25.6
A14: Slag-scarcity uplift from 2031 | B14: EUR/t | C14: =IF(C$3>=2031,cem3b_slag_scarcity_uplift_2031plus/100*price_cem3b_2026_delivered,0) -> 0 | D14: =IF(D$3>=2031,cem3b_slag_scarcity_uplift_2031plus/100*price_cem3b_2026_delivered,0) -> 0 | E14: =IF(E$3>=2031,cem3b_slag_scarcity_uplift_2031plus/100*price_cem3b_2026_delivered,0) -> 0 | F14: =IF(F$3>=2031,cem3b_slag_scarcity_uplift_2031plus/100*price_cem3b_2026_delivered,0) -> 0 | G14: =IF(G$3>=2031,cem3b_slag_scarcity_uplift_2031plus/100*price_cem3b_2026_delivered,0) -> 0 | H14: =IF(H$3>=2031,cem3b_slag_scarcity_uplift_2031plus/100*price_cem3b_2026_delivered,0) -> 11 | I14: =IF(I$3>=2031,cem3b_slag_scarcity_uplift_2031plus/100*price_cem3b_2026_delivered,0) -> 11 | J14: =IF(J$3>=2031,cem3b_slag_scarcity_uplift_2031plus/100*price_cem3b_2026_delivered,0) -> 11 | ... M14: =IF(M$3>=2031,cem3b_slag_scarcity_uplift_2031plus/100*price_cem3b_2026_delivered,0) -> 11
A15: CEM III/B price | B15: EUR/t | C15: =price_cem3b_2026_delivered+cement_carbon_passthrough/100*(C13-$C$13)+C14 -> 110 | D15: =price_cem3b_2026_delivered+cement_carbon_passthrough/100*(D13-$C$13)+D14 -> 110.425 | E15: =price_cem3b_2026_delivered+cement_carbon_passthrough/100*(E13-$C$13)+E14 -> 111.19 | F15: =price_cem3b_2026_delivered+cement_carbon_passthrough/100*(F13-$C$13)+F14 -> 113.06 | G15: =price_cem3b_2026_delivered+cement_carbon_passthrough/100*(G13-$C$13)+G14 -> 117.055 | H15: =price_cem3b_2026_delivered+cement_carbon_passthrough/100*(H13-$C$13)+H14 -> 130.35 | I15: =price_cem3b_2026_delivered+cement_carbon_passthrough/100*(I13-$C$13)+I14 -> 132.985 | J15: =price_cem3b_2026_delivered+cement_carbon_passthrough/100*(J13-$C$13)+J14 -> 136.045 | ... M15: =price_cem3b_2026_delivered+cement_carbon_passthrough/100*(M13-$C$13)+M14 -> 139.53
A16: Market-wide binder cost increase vs 2026 (avg mix) | B16: EUR/m3 | C16: =mix_plant_avg_binder_conv/1000*(C15-price_cem3b_2026_delivered) -> 0 | D16: =mix_plant_avg_binder_conv/1000*(D15-price_cem3b_2026_delivered) -> 0.13175 | E16: =mix_plant_avg_binder_conv/1000*(E15-price_cem3b_2026_delivered) -> 0.3689 | F16: =mix_plant_avg_binder_conv/1000*(F15-price_cem3b_2026_delivered) -> 0.9486 | G16: =mix_plant_avg_binder_conv/1000*(G15-price_cem3b_2026_delivered) -> 2.18705 | H16: =mix_plant_avg_binder_conv/1000*(H15-price_cem3b_2026_delivered) -> 6.3085 | I16: =mix_plant_avg_binder_conv/1000*(I15-price_cem3b_2026_delivered) -> 7.12535 | J16: =mix_plant_avg_binder_conv/1000*(J15-price_cem3b_2026_delivered) -> 8.07395 | ... M16: =mix_plant_avg_binder_conv/1000*(M15-price_cem3b_2026_delivered) -> 9.1543
A18: Prices (delivered, plant average)
A19: Market price, plant average (incl. pass-through of binder cost) | B19: EUR/m3 | C19: =price_plant_avg_all_classes*(1+price_real_escalation/100)^C$4+concrete_price_passthrough_of_market_binder_cost/100*C16+opt_price_delta_per_m3 -> 135 | D19: =price_plant_avg_all_classes*(1+price_real_escalation/100)^D$4+concrete_price_passthrough_of_market_binder_cost/100*D16+opt_price_delta_per_m3 -> 135.1054 | E19: =price_plant_avg_all_classes*(1+price_real_escalation/100)^E$4+concrete_price_passthrough_of_market_binder_cost/100*E16+opt_price_delta_per_m3 -> 135.29512 | F19: =price_plant_avg_all_classes*(1+price_real_escalation/100)^F$4+concrete_price_passthrough_of_market_binder_cost/100*F16+opt_price_delta_per_m3 -> 135.75888 | G19: =price_plant_avg_all_classes*(1+price_real_escalation/100)^G$4+concrete_price_passthrough_of_market_binder_cost/100*G16+opt_price_delta_per_m3 -> 136.74964 | H19: =price_plant_avg_all_classes*(1+price_real_escalation/100)^H$4+concrete_price_passthrough_of_market_binder_cost/100*H16+opt_price_delta_per_m3 -> 140.0468 | I19: =price_plant_avg_all_classes*(1+price_real_escalation/100)^I$4+concrete_price_passthrough_of_market_binder_cost/100*I16+opt_price_delta_per_m3 -> 140.70028 | J19: =price_plant_avg_all_classes*(1+price_real_escalation/100)^J$4+concrete_price_passthrough_of_market_binder_cost/100*J16+opt_price_delta_per_m3 -> 141.45916 | ... M19: =price_plant_avg_all_classes*(1+price_real_escalation/100)^M$4+concrete_price_passthrough_of_market_binder_cost/100*M16+opt_price_delta_per_m3 -> 142.32344
A20: Blended green premium on circular volume | B20: % | C20: =public_share_of_sales/100*green_premium_public/100+(1-public_share_of_sales/100)*green_premium_private/100 -> 0.012
A21: Price circular mixes (+ option: circular-only delta from its start year) | B21: EUR/m3 | C21: =C19*(1+$C$20)+IF(C$3>=opt_circ_delta_start_year,opt_circ_price_delta_per_m3,0) -> 136.62 | D21: =D19*(1+$C$20)+IF(D$3>=opt_circ_delta_start_year,opt_circ_price_delta_per_m3,0) -> 136.72666 | E21: =E19*(1+$C$20)+IF(E$3>=opt_circ_delta_start_year,opt_circ_price_delta_per_m3,0) -> 136.91866 | F21: =F19*(1+$C$20)+IF(F$3>=opt_circ_delta_start_year,opt_circ_price_delta_per_m3,0) -> 137.38799 | G21: =G19*(1+$C$20)+IF(G$3>=opt_circ_delta_start_year,opt_circ_price_delta_per_m3,0) -> 138.39064 | H21: =H19*(1+$C$20)+IF(H$3>=opt_circ_delta_start_year,opt_circ_price_delta_per_m3,0) -> 141.72736 | I21: =I19*(1+$C$20)+IF(I$3>=opt_circ_delta_start_year,opt_circ_price_delta_per_m3,0) -> 142.38868 | J21: =J19*(1+$C$20)+IF(J$3>=opt_circ_delta_start_year,opt_circ_price_delta_per_m3,0) -> 143.15667 | ... M21: =M19*(1+$C$20)+IF(M$3>=opt_circ_delta_start_year,opt_circ_price_delta_per_m3,0) -> 144.03132
A22: Price standard mixes | B22: EUR/m3 | C22: =C19 -> 135 | D22: =D19 -> 135.1054 | E22: =E19 -> 135.29512 | F22: =F19 -> 135.75888 | G22: =G19 -> 136.74964 | H22: =H19 -> 140.0468 | I22: =I19 -> 140.70028 | J22: =J19 -> 141.45916 | ... M22: =M19 -> 142.32344
A24: Revenue
A25: Revenue circular mixes | B25: EUR | C25: =C9*C21 -> 0 | D25: =D9*D21 -> 2871260 | E25: =E9*E21 -> 4542961.2 | F25: =F9*F21 -> 5770295.4 | G25: =G9*G21 -> 5812406.7 | H25: =H9*H21 -> 5952549.2 | I25: =I9*I21 -> 5980324.7 | J25: =J9*J21 -> 6012580.1 | ... M25: =M9*M21 -> 6049315.5
A26: Revenue standard mixes | B26: EUR | C26: =C10*C22 -> 0 | D26: =D10*D22 -> 1891475.6 | E26: =E10*E22 -> 2992728.1 | F26: =F10*F22 -> 3801248.6 | G26: =G10*G22 -> 3828989.9 | H26: =H10*H22 -> 3921310.4 | I26: =I10*I22 -> 3939607.8 | J26: =J10*J22 -> 3960856.5 | ... M26: =M10*M22 -> 3985056.3
A27: Option hook: extra revenue | B27: EUR | C27: =IF(C$4>=1+opt_start_delay,opt_extra_revenue_per_yr,0) -> 0 | D27: =IF(D$4>=1+opt_start_delay,opt_extra_revenue_per_yr,0) -> 0 | E27: =IF(E$4>=1+opt_start_delay,opt_extra_revenue_per_yr,0) -> 0 | F27: =IF(F$4>=1+opt_start_delay,opt_extra_revenue_per_yr,0) -> 0 | G27: =IF(G$4>=1+opt_start_delay,opt_extra_revenue_per_yr,0) -> 0 | H27: =IF(H$4>=1+opt_start_delay,opt_extra_revenue_per_yr,0) -> 0 | I27: =IF(I$4>=1+opt_start_delay,opt_extra_revenue_per_yr,0) -> 0 | J27: =IF(J$4>=1+opt_start_delay,opt_extra_revenue_per_yr,0) -> 0 | ... M27: =IF(M$4>=1+opt_start_delay,opt_extra_revenue_per_yr,0) -> 0
A29: Option A+B: on-site rubble acceptance and crushing (0 unless opt_crusher_on = 1)
A30: Crushing active (operating year and >= crusher start year) | B30: - | C30: =opt_crusher_on*IF(C$4>=1+opt_start_delay,1,0)*IF(C$3>=opt_crusher_start_year,1,0) -> 0 | D30: =opt_crusher_on*IF(D$4>=1+opt_start_delay,1,0)*IF(D$3>=opt_crusher_start_year,1,0) -> 0 | E30: =opt_crusher_on*IF(E$4>=1+opt_start_delay,1,0)*IF(E$3>=opt_crusher_start_year,1,0) -> 0 | F30: =opt_crusher_on*IF(F$4>=1+opt_start_delay,1,0)*IF(F$3>=opt_crusher_start_year,1,0) -> 0 | G30: =opt_crusher_on*IF(G$4>=1+opt_start_delay,1,0)*IF(G$3>=opt_crusher_start_year,1,0) -> 0 | H30: =opt_crusher_on*IF(H$4>=1+opt_start_delay,1,0)*IF(H$3>=opt_crusher_start_year,1,0) -> 0 | I30: =opt_crusher_on*IF(I$4>=1+opt_start_delay,1,0)*IF(I$3>=opt_crusher_start_year,1,0) -> 0 | J30: =opt_crusher_on*IF(J$4>=1+opt_start_delay,1,0)*IF(J$3>=opt_crusher_start_year,1,0) -> 0 | ... M30: =opt_crusher_on*IF(M$4>=1+opt_start_delay,1,0)*IF(M$3>=opt_crusher_start_year,1,0) -> 0
A31: Rubble intake (scales with ramp-up) | B31: t | C31: =opt_rubble_intake_tpy*C7*C30 -> 0 | D31: =opt_rubble_intake_tpy*D7*D30 -> 0 | E31: =opt_rubble_intake_tpy*E7*E30 -> 0 | F31: =opt_rubble_intake_tpy*F7*F30 -> 0 | G31: =opt_rubble_intake_tpy*G7*G30 -> 0 | H31: =opt_rubble_intake_tpy*H7*H30 -> 0 | I31: =opt_rubble_intake_tpy*I7*I30 -> 0 | J31: =opt_rubble_intake_tpy*J7*J30 -> 0 | ... M31: =opt_rubble_intake_tpy*M7*M30 -> 0
